<mujoco model="ur10e">
  <compiler angle="radian" meshdir="assets" autolimits="true"/>

  <option integrator="implicitfast"/>

  <default>
    <default class="ur10e">
      <material specular="0.5" shininess="0.25"/>
      <joint axis="0 1 0" range="-6.28319 6.28319" armature="0.1"/>
      <position ctrlrange="-6.2831 6.2831"/>
      <general biastype="affine" ctrlrange="-6.2831 6.2831" gainprm="5000" biasprm="0 -5000 -500"/>
      <default class="size4">
        <joint damping="10"/>
        <general forcerange="-330 330"/>
      </default>
      <default class="size3">
        <joint damping="5"/>
        <general forcerange="-150 150"/>
        <default class="size3_limited">
          <joint range="-3.1415 3.1415"/>
          <general ctrlrange="-3.1415 3.1415"/>
        </default>
      </default>
      <default class="size2">
        <joint damping="2"/>
        <general forcerange="-56 56"/>
      </default>
      <default class="visual">
        <geom type="mesh" contype="0" conaffinity="0" group="2"/>
      </default>
      <default class="collision">
        <geom type="capsule" group="3"/>
        <default class="eef_collision">
          <geom type="cylinder"/>
        </default>
      </default>
      <site size="0.001" rgba="0.5 0.5 0.5 0.3" group="4"/>
    </default>
    <default class="so101_gripper">
      <joint damping="0.60" frictionloss="0.052" armature="0.028"/>
      <position kp="17.8"/>
    </default>
    <default class="sts3215">
      <geom contype="0" conaffinity="0"/>
      <joint damping="0.60" frictionloss="0.052" armature="0.028"/>
      <position kp="17.8"/>
    </default>
    <default class="so101_visual">
      <geom type="mesh" contype="0" conaffinity="0" group="2"/>
    </default>
    <default class="so101_collision">
      <geom group="3" contype="1" conaffinity="1" friction="3 0.1 0.01"/>
    </default>
  </default>
  <asset>
    <material class="ur10e" name="black" rgba="0.033 0.033 0.033 1" />
    <material class="ur10e" name="jointgray" rgba="0.278 0.278 0.278 1" />
    <material class="ur10e" name="linkgray" rgba="0.82 0.82 0.82 1" />
    <material class="ur10e" name="urblue" rgba="0.49 0.678 0.8 1" />
    <material name="so101_gripper_material" rgba="1 0.82 0.12 1" />
    <material name="sts3215_03a_v1_material" rgba="0.1 0.1 0.1 1" />
    <material name="wrist_roll_follower_so101_v1_material" rgba="1 0.82 0.12 1" />
    <material name="moving_jaw_so101_v1_material" rgba="1 0.82 0.12 1" />
    <mesh file="base_0.obj" />
    <mesh file="base_1.obj" />
    <mesh file="shoulder_0.obj" />
    <mesh file="shoulder_1.obj" />
    <mesh file="shoulder_2.obj" />
    <mesh file="upperarm_0.obj" />
    <mesh file="upperarm_1.obj" />
    <mesh file="upperarm_2.obj" />
    <mesh file="upperarm_3.obj" />
    <mesh file="forearm_0.obj" />
    <mesh file="forearm_1.obj" />
    <mesh file="forearm_2.obj" />
    <mesh file="forearm_3.obj" />
    <mesh file="wrist1_0.obj" />
    <mesh file="wrist1_1.obj" />
    <mesh file="wrist1_2.obj" />
    <mesh file="wrist2_0.obj" />
    <mesh file="wrist2_1.obj" />
    <mesh file="wrist2_2.obj" />
    <mesh file="wrist3.obj" />
    <mesh name="wrist_roll_follower_so101" file="Wrist_Roll_Follower_SO101.STL" scale="0.001 0.001 0.001" />
    <mesh name="moving_jaw_so101" file="moving_jaw_so101_v1.stl" scale="0.001 0.001 0.001" />
    <mesh name="sts3215_03a_v1" file="sts3215_03a_v1.stl"/>
    <mesh name="wrist_roll_follower_so101_v1" file="Wrist_Roll_Follower_SO101.STL" scale="0.001 0.001 0.001" />
    <mesh name="moving_jaw_so101_v1" file="moving_jaw_so101_v1.stl"/>
  </asset>
  <worldbody>
    <light name="spotlight" mode="targetbodycom" target="wrist_2_link" pos="0 -1 2" />
    
    <body name="base" quat="1 0 0 1" childclass="ur10e">
      <inertial mass="4.0" pos="0 0 0" diaginertia="0.0061063308908 0.0061063308908 0.01125" />
      <geom mesh="base_0" material="black" class="visual" />
      <geom mesh="base_1" material="jointgray" class="visual" />
      <body name="shoulder_link" pos="0 0 0.181">
        <inertial pos="0 0 0" mass="7.778" diaginertia="0.0314743 0.0314743 0.0218756" />
        <joint name="shoulder_pan_joint" class="size4" axis="0 0 1" />
        <geom mesh="shoulder_0" material="urblue" class="visual" />
        <geom mesh="shoulder_1" material="black" class="visual" />
        <geom mesh="shoulder_2" material="jointgray" class="visual" />
        <geom class="collision" contype="2" conaffinity="1" size="0.078 0.08" pos="0 0 -0.05" />
        <body name="upper_arm_link" pos="0 0.176 0" quat="1 0 1 0">
          <inertial pos="0 0 0.3065" mass="12.93" diaginertia="0.423074 0.423074 0.0363656" />
          <joint name="shoulder_lift_joint" class="size4" />
          <geom mesh="upperarm_0" material="black" class="visual" />
          <geom mesh="upperarm_1" material="jointgray" class="visual" />
          <geom mesh="upperarm_2" material="urblue" class="visual" />
          <geom mesh="upperarm_3" material="linkgray" class="visual" />
          <geom class="collision" contype="2" conaffinity="1" pos="0 -0.05 0" quat="1 1 0 0" size="0.078 0.08" />
          <geom class="collision" contype="2" conaffinity="1" size="0.06 0.3" pos="0 0 0.3" />
          <body name="forearm_link" pos="0 -0.137 0.613">
            <inertial pos="0 0 0.2855" mass="3.87" diaginertia="0.11059 0.11059 0.0108844" />
            <joint name="elbow_joint" class="size3_limited" />
            <geom mesh="forearm_0" material="urblue" class="visual" />
            <geom mesh="forearm_1" material="black" class="visual" />
            <geom mesh="forearm_2" material="jointgray" class="visual" />
            <geom mesh="forearm_3" material="linkgray" class="visual" />
            <geom class="collision" contype="2" conaffinity="1" pos="0 0.08 0" quat="1 1 0 0" size="0.058 0.065" />
            <geom class="collision" contype="2" conaffinity="1" size="0.043 0.28" pos="0 0 0.29" />
            <body name="wrist_1_link" pos="0 0 0.571" quat="1 0 1 0">
              <inertial pos="0 0.135 0" quat="0.5 0.5 -0.5 0.5" mass="1.96" diaginertia="0.0055125 0.00510825 0.00510825" />
              <joint name="wrist_1_joint" class="size2" />
              <geom mesh="wrist1_0" material="black" class="visual" />
              <geom mesh="wrist1_1" material="urblue" class="visual" />
              <geom mesh="wrist1_2" material="jointgray" class="visual" />
              <geom class="collision" contype="2" conaffinity="1" pos="0 0.06 0" quat="1 1 0 0" size="0.05 0.07" />
              <body name="wrist_2_link" pos="0 0.135 0">
                <inertial pos="0 0 0.12" quat="0.5 0.5 -0.5 0.5" mass="1.96" diaginertia="0.0055125 0.00510825 0.00510825" />
                <joint name="wrist_2_joint" axis="0 0 1" class="size2" />
                <geom mesh="wrist2_0" material="black" class="visual" />
                <geom mesh="wrist2_1" material="urblue" class="visual" />
                <geom mesh="wrist2_2" material="jointgray" class="visual" />
                <geom class="collision" contype="2" conaffinity="1" size="0.046 0.065" pos="0 0 0.05" />
                <geom class="collision" contype="2" conaffinity="1" pos="0 0.028 0.12" quat="1 1 0 0" size="0.046 0.043" />
                <body name="wrist_3_link" pos="0 0 0.12">
                  <inertial pos="0 0.092 0" quat="0 1 -1 0" mass="0.202" diaginertia="0.000204525 0.000144346 0.000144346" />
                  <joint name="wrist_3_joint" class="size2" />
                  <geom material="linkgray" mesh="wrist3" class="visual" />
                  <geom class="eef_collision" contype="2" conaffinity="1" pos="0 0.097 0" quat="1 1 0 0" size="0.046 0.02" />
                  <site name="attachment_site" pos="0 0.12 0" quat="0.7071 -0.7071 0 0" size="0.015" group="1" rgba="1 0 0 1"/>
                  <!-- SO101 Gripper -->
                  <body name="gripper" pos="-0.04 0.23 -0.038" quat="-0.707107 0.707107 0 0.0">
                    <!-- Joint from wrist to gripper -->
                    <inertial pos="0.000213627 0.000245138 -0.025187" mass="0.087" fullinertia="2.75087e-05 4.33657e-05 3.45059e-05 -3.35241e-07 -5.7352e-06 -5.17847e-08"/>
                    <!-- Part sts3215_03a_v1_5 -->
                    <geom type="mesh" class="so101_visual" pos="0.05 -0.035 -0.08" quat="0.707107 -0.707107 1.66015e-15 6.45094e-15" mesh="sts3215_03a_v1" material="sts3215_03a_v1_material"/>
                    <geom type="mesh" class="so101_collision" pos="0.05 -0.035 -0.08" quat="0.707107 -0.707107 1.66015e-15 6.45094e-15" mesh="sts3215_03a_v1" material="sts3215_03a_v1_material"/>
                    <!-- Part wrist_roll_follower_so101_v1 -->
                    <geom type="mesh" class="so101_visual" pos="8.32667e-17 -0.000218214 0.000949706" quat="0 1 0 0" mesh="wrist_roll_follower_so101_v1" material="wrist_roll_follower_so101_v1_material"/>
                    <geom type="mesh" class="so101_collision" pos="8.32667e-17 -0.000218214 0.000949706" quat="0 1 0 0" mesh="wrist_roll_follower_so101_v1" material="wrist_roll_follower_so101_v1_material"/>
                    <!-- Frame gripperframe -->
                    <site group="3" name="gripperframe" pos="-0.0079 -0.000218121 -0.0981274" quat="0.707107 -0 0.707107 -2.37788e-17"/>
                    <!-- Link moving_jaw_so101_v1 -->
                    <body name="reference_marker" pos="-0.0079 0 -0.0981274" gravcomp="0">
                      <inertial pos="0 0 0" mass="0.001" diaginertia="0.000001 0.000001 0.000001"/>
                      <geom name="reference_sphere" type="sphere" size="0.002" rgba="1 0 0 1" contype="0" conaffinity="0"/>
                      <site name="end_effector_marker" pos="0 0 0" size="0.0001" rgba="1 0 0 0"/>
                    </body>
                    <body name="moving_jaw_so101_v1" pos="0.065 -0.057 -0.08" quat="0.707107 -0.707107 -1.85362e-08 1.85362e-08">
                      <!-- Joint from gripper to moving_jaw_so101_v1 -->
                      <joint axis="0 0 1" name="gripper" type="hinge" range="-0.17453297762778586 1.7453291995659765" class="sts3215"/>
                      <inertial pos="-0.00157495 -0.0300244 0.0192755" mass="0.012" fullinertia="6.61427e-06 1.89032e-06 5.28738e-06 -3.19807e-07 -5.90717e-09 -1.09945e-07"/>
                      <!-- Part moving_jaw_so101_v1 -->
                      <geom type="mesh" class="so101_visual" pos="-5.55112e-17 -5.55112e-17 0.0189" quat="1 -0 3.00524e-16 -2.00834e-17" mesh="moving_jaw_so101_v1" material="moving_jaw_so101_v1_material"/>
                      <geom type="mesh" class="so101_collision" pos="-5.55112e-17 -5.55112e-17 0.0189" quat="1 -0 3.00524e-16 -2.00834e-17" mesh="moving_jaw_so101_v1" material="moving_jaw_so101_v1_material"/>
                    </body>
                  </body>
                </body>
              </body>
            </body>
          </body>
        </body>
      </body>
    </body>
  </worldbody>
  <actuator>
    <general class="size4" name="shoulder_pan" joint="shoulder_pan_joint" />
    <general class="size4" name="shoulder_lift" joint="shoulder_lift_joint" />
    <general class="size3_limited" name="elbow" joint="elbow_joint" />
    <general class="size2" name="wrist_1" joint="wrist_1_joint" />
    <general class="size2" name="wrist_2" joint="wrist_2_joint" />
    <general class="size2" name="wrist_3" joint="wrist_3_joint" />
    <position class="sts3215" name="gripper" joint="gripper" forcerange="-3.35 3.35" ctrlrange="-0.17453 1.74533"/>
  </actuator>
</mujoco>
